Workbook

Sheet Cover
G1: DATA • INSIGHTS • GROWTH
B17: 📊 | D17: PROJECT
D20: REPORT
A24: ● ● ●
A26: Data Analysis using Microsoft Excel
B29: Submitted by | E29: Thakkar Disha
B30: GR ID | E30: 12782
B31: Date | E31: 46308
A33: Analyze • Create • Achieve

Sheet Contents
A1: Contents (click a name to open the sheet)
A2: 1 | B2: Dashboard | C2: KPIs, 4 charts and key insights
A3: 2 | B3: Guide | C3: Instructions and how-to steps (pivot, slicers, ToolPak, Goal Seek)
A4: 3 | B4: Raw Data | C4: 250 customer transactions (your Final Project Dataset) + DATEDIF / EOMONTH helpers
A5: 4 | B5: Analysis | C5: Date functions, customer GroupBy, high-value customers, products, regions, monthly trend
A6: 5 | B6: Filter | C6: Region dropdown returning all matching transactions
A7: 6 | B7: What-If | C7: Scenario table (Best / Base / Worst) and Goal Seek
A8: 7 | B8: Regression | C8: Linear regression: Quantity vs Total Amount (SLOPE, INTERCEPT, R²)
A9: 8 | B9: Visualizations | C9: Bar, line, pie, top-customers bar and scatter with trendline
A10: 9 | B10: Final Report | C10: Auto-updating insights and storytelling

Sheet Dashboard
A1: DATA INTELLIGENCE DASHBOARD
A2: ="Data: "&TEXT(Analysis!B6,"dd-mmm-yyyy")&" to "&TEXT(Analysis!B7,"dd-mmm-yyyy")&" | Refreshed: "&TEXT(Analysis!B5,"dd-mmm-yyyy hh:mm") -> Data: 11-Apr-2024 to 11-Apr-2025 | Refreshed: 09-Oct-2026 10:58
A3: TOTAL REVENUE | C3: TOTAL ORDERS | E3: AVG ORDER VALUE | G3: ACTIVE CUSTOMERS
A4: =SUM('Raw Data'!$N$2:$N$251) -> 229192.47 | C4: =COUNTA('Raw Data'!$A$2:$A$251) -> 250 | E4: =A4/C4 -> 916.76988 | G4: =COUNTIF(Analysis!C14:C63,">0") -> 50
A6: TOP CUSTOMER | C6: TOP PRODUCT (REVENUE) | E6: TOP REGION | G6: LAST FULL MONTH vs PRIOR
A7: =Analysis!B65 -> Mark Carter | C7: =Analysis!B83 -> Laptop | E7: =Analysis!B93 -> East | G7: =Analysis!F127 -> 0.23834149

Sheet Guide
A1: PR. Final Project – Data Intelligence Dashboard
A3: DATASET | B3: 'Raw Data' holds your 'Final Project Dataset' (250 transactions, columns A-N exactly as given). Columns O-Q are helper formulas (DATEDIF, EOMONTH, filter helper).
A4: COLOUR CODE | B4: Blue text / yellow fill = cells you can edit. Black = formulas.
A5: PIVOT TABLES (do by hand) | B5: Raw Data → Insert > PivotTable → new sheet 'Pivot'. Build: (1) Region × Total_Amount, (2) Product_Name × Total_Amount, (3) Date by Months × Total_Amount. Then PivotCharts: Bar (Region), Line (Month), Pie (Product).
A6: SLICERS & TIMELINE (do by hand) | B6: Click a PivotTable → PivotTable Analyze > Insert Slicer → Region, Category, Customer_Segment. Insert Timeline → Date. Connect them via Report Connections so they control every pivot. Add pivot charts to a Dashboard area.
A7: FILTER FUNCTION | B7: Excel 365: =FILTER('Raw Data'!A2:N251,'Raw Data'!K2:K251="West","No data"). A version that works in any Excel is already on the 'Filter' sheet.
A8: TIMESTAMP (NOW + iterative calc) | B8: File > Options > Formulas > tick 'Enable iterative calculation'. In a blank sheet: A2 = Order ID, B2: =IF(A2="","",IF(B2="",NOW(),B2)). Type an ID in A2 and the time freezes in B2. Format B2 as dd-mmm-yyyy hh:mm:ss.
A9: SCENARIO MANAGER | B9: What-If sheet: Data > What-If Analysis > Scenario Manager > Add. Changing cells B5:B7. Best (10%, 8%, 1%), Base (5%, 2%, 3%), Worst (-2%, -5%, 6%) → Summary with result cell B8.
A10: GOAL SEEK | B10: Data > What-If Analysis > Goal Seek: Set cell What-If!B8, To value = What-If!B18, By changing cell What-If!B5.
A11: DATA ANALYSIS TOOLPAK | B11: File > Options > Add-ins > Manage Excel Add-ins > Go > tick Analysis ToolPak. Then Data > Data Analysis > Regression: Y = Raw Data!N2:N251, X = Raw Data!H2:H251. Compare with the 'Regression' sheet.
A12: COVERED ALREADY | B12: TODAY, NOW, DATEDIF, EOMONTH, EDATE · SUMIFS/COUNTIFS GroupBy · icon-set arrows & data bars · High-Value customers · most frequent product · list compare (MATCH) · abbreviations (LEFT/MID/FIND/UPPER/TEXT) · KPI conditional formatting · regression (SLOPE/INTERCEPT/RSQ) · dynamic insights.

Sheet Raw Data
A1: Transaction_ID | B1: Date | C1: Customer_ID | D1: Customer_Name | E1: Product_ID | F1: Product_Name | G1: Category | H1: Quantity | I1: Unit_Price | J1: Payment_Method | K1: Region | L1: Customer_Segment | M1: Customer_Since | N1: Total_Amount | O1: Days Ago (DATEDIF) | P1: Month End (EOMONTH) | Q1: Filter Helper
A2: TRX0155 | B2: 45393 | C2: CUST023 | D2: Paul Baker | E2: P009 | F2: Monitor | G2: Electronics | H2: 3 | I2: 249.99 | J2: Cash | K2: Central | L2: Basic | M2: 44425 | N2: =H2*I2 -> 749.97 | O2: =DATEDIF(B2,TODAY(),"d") -> 911 | P2: =EOMONTH(B2,0) -> 45412 | Q2: =IF(K2=Filter!$B$2,COUNTIF(K$2:K2,Filter!$B$2),"")
A3: TRX0023 | B3: 45396 | C3: CUST013 | D3: Joseph Jackson | E3: P009 | F3: Monitor | G3: Electronics | H3: 3 | I3: 249.99 | J3: Credit Card | K3: Central | L3: Premium | M3: 44575 | N3: =H3*I3 -> 749.97 | O3: =DATEDIF(B3,TODAY(),"d") -> 908 | P3: =EOMONTH(B3,0) -> 45412 | Q3: =IF(K3=Filter!$B$2,COUNTIF(K$2:K3,Filter!$B$2),"")
A4: TRX0139 | B4: 45399 | C4: CUST021 | D4: Kevin Scott | E4: P005 | F4: Blender | G4: Appliances | H4: 3 | I4: 59.99 | J4: PayPal | K4: South | L4: Standard | M4: 45262 | N4: =H4*I4 -> 179.97 | O4: =DATEDIF(B4,TODAY(),"d") -> 905 | P4: =EOMONTH(B4,0) -> 45412 | Q4: =IF(K4=Filter!$B$2,COUNTIF(K$2:K4,Filter!$B$2),"")
A5: TRX0043 | B5: 45400 | C5: CUST046 | D5: Kathleen Bennett | E5: P005 | F5: Blender | G5: Appliances | H5: 3 | I5: 59.99 | J5: Cash | K5: North | L5: Premium | M5: 45114 | N5: =H5*I5 -> 179.97 | O5: =DATEDIF(B5,TODAY(),"d") -> 904 | P5: =EOMONTH(B5,0) -> 45412 | Q5: =IF(K5=Filter!$B$2,COUNTIF(K$2:K5,Filter!$B$2),"")
A6: TRX0212 | B6: 45400 | C6: CUST003 | D6: Michael Brown | E6: P008 | F6: Bookshelf | G6: Furniture | H6: 5 | I6: 149.99 | J6: Credit Card | K6: North | L6: Premium | M6: 45295 | N6: =H6*I6 -> 749.95 | O6: =DATEDIF(B6,TODAY(),"d") -> 904 | P6: =EOMONTH(B6,0) -> 45412 | Q6: =IF(K6=Filter!$B$2,COUNTIF(K$2:K6,Filter!$B$2),"")
A7: TRX0092 | B7: 45403 | C7: CUST024 | D7: Dorothy Nelson | E7: P005 | F7: Blender | G7: Appliances | H7: 2 | I7: 59.99 | J7: Cash | K7: West | L7: Standard | M7: 44746 | N7: =H7*I7 -> 119.98 | O7: =DATEDIF(B7,TODAY(),"d") -> 901 | P7: =EOMONTH(B7,0) -> 45412 | Q7: =IF(K7=Filter!$B$2,COUNTIF(K$2:K7,Filter!$B$2),"") -> 1
A8: TRX0193 | B8: 45403 | C8: CUST024 | D8: Dorothy Nelson | E8: P003 | F8: Headphones | G8: Electronics | H8: 5 | I8: 149.99 | J8: Credit Card | K8: Central | L8: Standard | M8: 44418 | N8: =H8*I8 -> 749.95 | O8: =DATEDIF(B8,TODAY(),"d") -> 901 | P8: =EOMONTH(B8,0) -> 45412 | Q8: =IF(K8=Filter!$B$2,COUNTIF(K$2:K8,Filter!$B$2),"")
A9: TRX0240 | B9: 45403 | C9: CUST017 | D9: Charles Allen | E9: P005 | F9: Blender | G9: Appliances | H9: 3 | I9: 59.99 | J9: Debit Card | K9: South | L9: Basic | M9: 45007 | N9: =H9*I9 -> 179.97 | O9: =DATEDIF(B9,TODAY(),"d") -> 901 | P9: =EOMONTH(B9,0) -> 45412 | Q9: =IF(K9=Filter!$B$2,COUNTIF(K$2:K9,Filter!$B$2),"")
A10: TRX0135 | B10: 45405 | C10: CUST009 | D10: Robert Thomas | E10: P001 | F10: Laptop | G10: Electronics | H10: 3 | I10: 899.99 | J10: PayPal | K10: East | L10: Standard | M10: 45299 | N10: =H10*I10 -> 2699.97 | O10: =DATEDIF(B10,TODAY(),"d") -> 899 | P10: =EOMONTH(B10,0) -> 45412 | Q10: =IF(K10=Filter!$B$2,COUNTIF(K$2:K10,Filter!$B$2),"")
A11: TRX0185 | B11: 45408 | C11: CUST026 | D11: Karen Hill | E11: P005 | F11: Blender | G11: Appliances | H11: 3 | I11: 59.99 | J11: Cash | K11: West | L11: Premium | M11: 45207 | N11: =H11*I11 -> 179.97 | O11: =DATEDIF(B11,TODAY(),"d") -> 896 | P11: =EOMONTH(B11,0) -> 45412 | Q11: =IF(K11=Filter!$B$2,COUNTIF(K$2:K11,Filter!$B$2),"") -> 2
A12: TRX0138 | B12: 45408 | C12: CUST022 | D12: Susan Green | E12: P008 | F12: Bookshelf | G12: Furniture | H12: 1 | I12: 149.99 | J12: Credit Card | K12: West | L12: Standard | M12: 45103 | N12: =H12*I12 -> 149.99 | O12: =DATEDIF(B12,TODAY(),"d") -> 896 | P12: =EOMONTH(B12,0) -> 45412 | Q12: =IF(K12=Filter!$B$2,COUNTIF(K$2:K12,Filter!$B$2),"") -> 3
A13: TRX0209 | B13: 45408 | C13: CUST046 | D13: Kathleen Bennett | E13: P008 | F13: Bookshelf | G13: Furniture | H13: 5 | I13: 149.99 | J13: Debit Card | K13: North | L13: Basic | M13: 44830 | N13: =H13*I13 -> 749.95 | O13: =DATEDIF(B13,TODAY(),"d") -> 896 | P13: =EOMONTH(B13,0) -> 45412 | Q13: =IF(K13=Filter!$B$2,COUNTIF(K$2:K13,Filter!$B$2),"")
... A251: TRX0064 | B251: 45758 | C251: CUST031 | D251: Steven Turner | E251: P010 | F251: Keyboard | G251: Electronics | H251: 3 | I251: 89.99 | J251: Debit Card | K251: North | L251: Premium | M251: 44878 | N251: =H251*I251 -> 269.97 | O251: =DATEDIF(B251,TODAY(),"d") -> 546 | P251: =EOMONTH(B251,0) -> 45777 | Q251: =IF(K251=Filter!$B$2,COUNTIF(K$2:K251,Filter!$B$2),"")

Sheet Analysis
A1: Analysis – all formulas are live and read from 'Raw Data'
A3: 1. Date & Time Functions (TODAY, NOW, DATEDIF, EOMONTH)
A4: Today | B4: =TODAY() -> 46304
A5: Now (date + time) | B5: =NOW() -> 46304.457
A6: First transaction | B6: =MIN('Raw Data'!$B$2:$B$251) -> 45393
A7: Last transaction | B7: =MAX('Raw Data'!$B$2:$B$251) -> 45758
A8: Days since last transaction | B8: =B4-B7 -> 546
A9: Months of data (DATEDIF) | B9: =DATEDIF(B6,B7,"m") -> 12
A10: Month-end of last transaction (EOMONTH) | B10: =EOMONTH(B7,0) -> 45777
A11: 2. Customers – GroupBy via SUMIFS / COUNTIFS (High-Value, Abbreviations, List Compare)
A12: High-value threshold (top 25% – 75th percentile) | B12: =PERCENTILE(D14:D63,0.75) -> 6304.8075
A13: Customer | B13: Abbrev. (TEXT fn) | C13: Orders | D13: Total Revenue | E13: Avg Order | F13: Rank | G13: Segment | H13: In VIP List? | K13: Reference VIP List | L13: Matching Names (both lists)
A14: Mark Carter | B14: =UPPER(LEFT(A14,1)&MID(A14,FIND(" ",A14)+1,1))&"-"&TEXT(F14,"00") -> MC-01 | C14: =COUNTIFS('Raw Data'!$D$2:$D$251,A14) -> 12 | D14: =SUMIFS('Raw Data'!$N$2:$N$251,'Raw Data'!$D$2:$D$251,A14) -> 15659.65 | E14: =IFERROR(D14/C14,0) -> 1304.9708 | F14: =RANK(D14,$D$14:$D$63) -> 1 | G14: =IF(D14>=$B$12,"High-Value","Regular") -> High-Value | H14: =IF(COUNTIF($K$14:$K$23,A14)>0,"Yes","No") -> Yes | K14: Mark Carter | L14: =IF(ISNUMBER(MATCH(K14,$A$14:$A$63,0)),K14,"") -> Mark Carter
A15: Edward Mitchell | B15: =UPPER(LEFT(A15,1)&MID(A15,FIND(" ",A15)+1,1))&"-"&TEXT(F15,"00") -> EM-02 | C15: =COUNTIFS('Raw Data'!$D$2:$D$251,A15) -> 6 | D15: =SUMIFS('Raw Data'!$N$2:$N$251,'Raw Data'!$D$2:$D$251,A15) -> 11919.77 | E15: =IFERROR(D15/C15,0) -> 1986.6283 | F15: =RANK(D15,$D$14:$D$63) -> 2 | G15: =IF(D15>=$B$12,"High-Value","Regular") -> High-Value | H15: =IF(COUNTIF($K$14:$K$23,A15)>0,"Yes","No") -> No | K15: Barbara Young | L15: =IF(ISNUMBER(MATCH(K15,$A$14:$A$63,0)),K15,"") -> Barbara Young
A16: Barbara Young | B16: =UPPER(LEFT(A16,1)&MID(A16,FIND(" ",A16)+1,1))&"-"&TEXT(F16,"00") -> BY-03 | C16: =COUNTIFS('Raw Data'!$D$2:$D$251,A16) -> 5 | D16: =SUMIFS('Raw Data'!$N$2:$N$251,'Raw Data'!$D$2:$D$251,A16) -> 10649.8 | E16: =IFERROR(D16/C16,0) -> 2129.96 | F16: =RANK(D16,$D$14:$D$63) -> 3 | G16: =IF(D16>=$B$12,"High-Value","Regular") -> High-Value | H16: =IF(COUNTIF($K$14:$K$23,A16)>0,"Yes","No") -> Yes | K16: Dorothy Nelson | L16: =IF(ISNUMBER(MATCH(K16,$A$14:$A$63,0)),K16,"") -> Dorothy Nelson
A17: Patricia Moore | B17: =UPPER(LEFT(A17,1)&MID(A17,FIND(" ",A17)+1,1))&"-"&TEXT(F17,"00") -> PM-04 | C17: =COUNTIFS('Raw Data'!$D$2:$D$251,A17) -> 8 | D17: =SUMIFS('Raw Data'!$N$2:$N$251,'Raw Data'!$D$2:$D$251,A17) -> 9799.73 | E17: =IFERROR(D17/C17,0) -> 1224.9662 | F17: =RANK(D17,$D$14:$D$63) -> 4 | G17: =IF(D17>=$B$12,"High-Value","Regular") -> High-Value | H17: =IF(COUNTIF($K$14:$K$23,A17)>0,"Yes","No") -> No | K17: Joseph Jackson | L17: =IF(ISNUMBER(MATCH(K17,$A$14:$A$63,0)),K17,"") -> Joseph Jackson
A18: Paul Baker | B18: =UPPER(LEFT(A18,1)&MID(A18,FIND(" ",A18)+1,1))&"-"&TEXT(F18,"00") -> PB-05 | C18: =COUNTIFS('Raw Data'!$D$2:$D$251,A18) -> 8 | D18: =SUMIFS('Raw Data'!$N$2:$N$251,'Raw Data'!$D$2:$D$251,A18) -> 8309.74 | E18: =IFERROR(D18/C18,0) -> 1038.7175 | F18: =RANK(D18,$D$14:$D$63) -> 5 | G18: =IF(D18>=$B$12,"High-Value","Regular") -> High-Value | H18: =IF(COUNTIF($K$14:$K$23,A18)>0,"Yes","No") -> No | K18: Peter Richardson | L18: =IF(ISNUMBER(MATCH(K18,$A$14:$A$63,0)),K18,"") -> Peter Richardson
A19: Dorothy Nelson | B19: =UPPER(LEFT(A19,1)&MID(A19,FIND(" ",A19)+1,1))&"-"&TEXT(F19,"00") -> DN-06 | C19: =COUNTIFS('Raw Data'!$D$2:$D$251,A19) -> 6 | D19: =SUMIFS('Raw Data'!$N$2:$N$251,'Raw Data'!$D$2:$D$251,A19) -> 8269.79 | E19: =IFERROR(D19/C19,0) -> 1378.2983 | F19: =RANK(D19,$D$14:$D$63) -> 6 | G19: =IF(D19>=$B$12,"High-Value","Regular") -> High-Value | H19: =IF(COUNTIF($K$14:$K$23,A19)>0,"Yes","No") -> Yes | K19: Douglas Watson | L19: =IF(ISNUMBER(MATCH(K19,$A$14:$A$63,0)),K19,"") -> Douglas Watson
A20: Karen Hill | B20: =UPPER(LEFT(A20,1)&MID(A20,FIND(" ",A20)+1,1))&"-"&TEXT(F20,"00") -> KH-07 | C20: =COUNTIFS('Raw Data'!$D$2:$D$251,A20) -> 8 | D20: =SUMIFS('Raw Data'!$N$2:$N$251,'Raw Data'!$D$2:$D$251,A20) -> 8009.77 | E20: =IFERROR(D20/C20,0) -> 1001.2213 | F20: =RANK(D20,$D$14:$D$63) -> 7 | G20: =IF(D20>=$B$12,"High-Value","Regular") -> High-Value | H20: =IF(COUNTIF($K$14:$K$23,A20)>0,"Yes","No") -> No | K20: Elizabeth Hall | L20: =IF(ISNUMBER(MATCH(K20,$A$14:$A$63,0)),K20,"") -> Elizabeth Hall
A21: Daniel King | B21: =UPPER(LEFT(A21,1)&MID(A21,FIND(" ",A21)+1,1))&"-"&TEXT(F21,"00") -> DK-08 | C21: =COUNTIFS('Raw Data'!$D$2:$D$251,A21) -> 7 | D21: =SUMIFS('Raw Data'!$N$2:$N$251,'Raw Data'!$D$2:$D$251,A21) -> 7309.8 | E21: =IFERROR(D21/C21,0) -> 1044.2571 | F21: =RANK(D21,$D$14:$D$63) -> 8 | G21: =IF(D21>=$B$12,"High-Value","Regular") -> High-Value | H21: =IF(COUNTIF($K$14:$K$23,A21)>0,"Yes","No") -> No | K21: Zoya Khan | L21: =IF(ISNUMBER(MATCH(K21,$A$14:$A$63,0)),K21,"")
A22: Lawrence Reed | B22: =UPPER(LEFT(A22,1)&MID(A22,FIND(" ",A22)+1,1))&"-"&TEXT(F22,"00") -> LR-09 | C22: =COUNTIFS('Raw Data'!$D$2:$D$251,A22) -> 8 | D22: =SUMIFS('Raw Data'!$N$2:$N$251,'Raw Data'!$D$2:$D$251,A22) -> 6989.77 | E22: =IFERROR(D22/C22,0) -> 873.72125 | F22: =RANK(D22,$D$14:$D$63) -> 9 | G22: =IF(D22>=$B$12,"High-Value","Regular") -> High-Value | H22: =IF(COUNTIF($K$14:$K$23,A22)>0,"Yes","No") -> No | K22: Dev Anand | L22: =IF(ISNUMBER(MATCH(K22,$A$14:$A$63,0)),K22,"")
A23: Joseph Jackson | B23: =UPPER(LEFT(A23,1)&MID(A23,FIND(" ",A23)+1,1))&"-"&TEXT(F23,"00") -> JJ-10 | C23: =COUNTIFS('Raw Data'!$D$2:$D$251,A23) -> 5 | D23: =SUMIFS('Raw Data'!$N$2:$N$251,'Raw Data'!$D$2:$D$251,A23) -> 6949.84 | E23: =IFERROR(D23/C23,0) -> 1389.968 | F23: =RANK(D23,$D$14:$D$63) -> 10 | G23: =IF(D23>=$B$12,"High-Value","Regular") -> High-Value | H23: =IF(COUNTIF($K$14:$K$23,A23)>0,"Yes","No") -> Yes | K23: Maya Bose | L23: =IF(ISNUMBER(MATCH(K23,$A$14:$A$63,0)),K23,"")
A24: Helen Roberts | B24: =UPPER(LEFT(A24,1)&MID(A24,FIND(" ",A24)+1,1))&"-"&TEXT(F24,"00") -> HR-11 | C24: =COUNTIFS('Raw Data'!$D$2:$D$251,A24) -> 7 | D24: =SUMIFS('Raw Data'!$N$2:$N$251,'Raw Data'!$D$2:$D$251,A24) -> 6459.79 | E24: =IFERROR(D24/C24,0) -> 922.82714 | F24: =RANK(D24,$D$14:$D$63) -> 11 | G24: =IF(D24>=$B$12,"High-Value","Regular") -> High-Value | H24: =IF(COUNTIF($K$14:$K$23,A24)>0,"Yes","No") -> No | K24: Blue = editable input list
A25: Gerald Murphy | B25: =UPPER(LEFT(A25,1)&MID(A25,FIND(" ",A25)+1,1))&"-"&TEXT(F25,"00") -> GM-12 | C25: =COUNTIFS('Raw Data'!$D$2:$D$251,A25) -> 4 | D25: =SUMIFS('Raw Data'!$N$2:$N$251,'Raw Data'!$D$2:$D$251,A25) -> 6379.87 | E25: =IFERROR(D25/C25,0) -> 1594.9675 | F25: =RANK(D25,$D$14:$D$63) -> 12 | G25: =IF(D25>=$B$12,"High-Value","Regular") -> High-Value | H25: =IF(COUNTIF($K$14:$K$23,A25)>0,"Yes","No") -> No
A26: Sandra Phillips | B26: =UPPER(LEFT(A26,1)&MID(A26,FIND(" ",A26)+1,1))&"-"&TEXT(F26,"00") -> SP-13 | C26: =COUNTIFS('Raw Data'!$D$2:$D$251,A26) -> 5 | D26: =SUMIFS('Raw Data'!$N$2:$N$251,'Raw Data'!$D$2:$D$251,A26) -> 6349.83 | E26: =IFERROR(D26/C26,0) -> 1269.966 | F26: =RANK(D26,$D$14:$D$63) -> 13 | G26: =IF(D26>=$B$12,"High-Value","Regular") -> High-Value | H26: =IF(COUNTIF($K$14:$K$23,A26)>0,"Yes","No") -> No
A27: Michael Brown | B27: =UPPER(LEFT(A27,1)&MID(A27,FIND(" ",A27)+1,1))&"-"&TEXT(F27,"00") -> MB-14 | C27: =COUNTIFS('Raw Data'!$D$2:$D$251,A27) -> 9 | D27: =SUMIFS('Raw Data'!$N$2:$N$251,'Raw Data'!$D$2:$D$251,A27) -> 6169.74 | E27: =IFERROR(D27/C27,0) -> 685.52667 | F27: =RANK(D27,$D$14:$D$63) -> 14 | G27: =IF(D27>=$B$12,"High-Value","Regular") -> Regular | H27: =IF(COUNTIF($K$14:$K$23,A27)>0,"Yes","No") -> No
A28: Peter Richardson | B28: =UPPER(LEFT(A28,1)&MID(A28,FIND(" ",A28)+1,1))&"-"&TEXT(F28,"00") -> PR-15 | C28: =COUNTIFS('Raw Data'!$D$2:$D$251,A28) -> 5 | D28: =SUMIFS('Raw Data'!$N$2:$N$251,'Raw Data'!$D$2:$D$251,A28) -> 5949.85 | E28: =IFERROR(D28/C28,0) -> 1189.97 | F28: =RANK(D28,$D$14:$D$63) -> 15 | G28: =IF(D28>=$B$12,"High-Value","Regular") -> Regular | H28: =IF(COUNTIF($K$14:$K$23,A28)>0,"Yes","No") -> Yes
A29: Betty Campbell | B29: =UPPER(LEFT(A29,1)&MID(A29,FIND(" ",A29)+1,1))&"-"&TEXT(F29,"00") -> BC-16 | C29: =COUNTIFS('Raw Data'!$D$2:$D$251,A29) -> 5 | D29: =SUMIFS('Raw Data'!$N$2:$N$251,'Raw Data'!$D$2:$D$251,A29) -> 5649.84 | E29: =IFERROR(D29/C29,0) -> 1129.968 | F29: =RANK(D29,$D$14:$D$63) -> 16 | G29: =IF(D29>=$B$12,"High-Value","Regular") -> Regular | H29: =IF(COUNTIF($K$14:$K$23,A29)>0,"Yes","No") -> No
A30: Sharon Butler | B30: =UPPER(LEFT(A30,1)&MID(A30,FIND(" ",A30)+1,1))&"-"&TEXT(F30,"00") -> SB-17 | C30: =COUNTIFS('Raw Data'!$D$2:$D$251,A30) -> 6 | D30: =SUMIFS('Raw Data'!$N$2:$N$251,'Raw Data'!$D$2:$D$251,A30) -> 5619.87 | E30: =IFERROR(D30/C30,0) -> 936.645 | F30: =RANK(D30,$D$14:$D$63) -> 17 | G30: =IF(D30>=$B$12,"High-Value","Regular") -> Regular | H30: =IF(COUNTIF($K$14:$K$23,A30)>0,"Yes","No") -> No
A31: Harry Morgan | B31: =UPPER(LEFT(A31,1)&MID(A31,FIND(" ",A31)+1,1))&"-"&TEXT(F31,"00") -> HM-18 | C31: =COUNTIFS('Raw Data'!$D$2:$D$251,A31) -> 4 | D31: =SUMIFS('Raw Data'!$N$2:$N$251,'Raw Data'!$D$2:$D$251,A31) -> 5519.89 | E31: =IFERROR(D31/C31,0) -> 1379.9725 | F31: =RANK(D31,$D$14:$D$63) -> 18 | G31: =IF(D31>=$B$12,"High-Value","Regular") -> Regular | H31: =IF(COUNTIF($K$14:$K$23,A31)>0,"Yes","No") -> No
A32: Sarah Davis | B32: =UPPER(LEFT(A32,1)&MID(A32,FIND(" ",A32)+1,1))&"-"&TEXT(F32,"00") -> SD-19 | C32: =COUNTIFS('Raw Data'!$D$2:$D$251,A32) -> 5 | D32: =SUMIFS('Raw Data'!$N$2:$N$251,'Raw Data'!$D$2:$D$251,A32) -> 5499.81 | E32: =IFERROR(D32/C32,0) -> 1099.962 | F32: =RANK(D32,$D$14:$D$63) -> 19 | G32: =IF(D32>=$B$12,"High-Value","Regular") -> Regular | H32: =IF(COUNTIF($K$14:$K$23,A32)>0,"Yes","No") -> No
A33: Charles Allen | B33: =UPPER(LEFT(A33,1)&MID(A33,FIND(" ",A33)+1,1))&"-"&TEXT(F33,"00") -> CA-20 | C33: =COUNTIFS('Raw Data'!$D$2:$D$251,A33) -> 9 | D33: =SUMIFS('Raw Data'!$N$2:$N$251,'Raw Data'!$D$2:$D$251,A33) -> 5089.73 | E33: =IFERROR(D33/C33,0) -> 565.52556 | F33: =RANK(D33,$D$14:$D$63) -> 20 | G33: =IF(D33>=$B$12,"High-Value","Regular") -> Regular | H33: =IF(COUNTIF($K$14:$K$23,A33)>0,"Yes","No") -> No
A34: Douglas Watson | B34: =UPPER(LEFT(A34,1)&MID(A34,FIND(" ",A34)+1,1))&"-"&TEXT(F34,"00") -> DW-21 | C34: =COUNTIFS('Raw Data'!$D$2:$D$251,A34) -> 4 | D34: =SUMIFS('Raw Data'!$N$2:$N$251,'Raw Data'!$D$2:$D$251,A34) -> 4829.89 | E34: =IFERROR(D34/C34,0) -> 1207.4725 | F34: =RANK(D34,$D$14:$D$63) -> 21 | G34: =IF(D34>=$B$12,"High-Value","Regular") -> Regular | H34: =IF(COUNTIF($K$14:$K$23,A34)>0,"Yes","No") -> Yes
A35: Virginia Sanders | B35: =UPPER(LEFT(A35,1)&MID(A35,FIND(" ",A35)+1,1))&"-"&TEXT(F35,"00") -> VS-22 | C35: =COUNTIFS('Raw Data'!$D$2:$D$251,A35) -> 6 | D35: =SUMIFS('Raw Data'!$N$2:$N$251,'Raw Data'!$D$2:$D$251,A35) -> 4789.79 | E35: =IFERROR(D35/C35,0) -> 798.29833 | F35: =RANK(D35,$D$14:$D$63) -> 22 | G35: =IF(D35>=$B$12,"High-Value","Regular") -> Regular | H35: =IF(COUNTIF($K$14:$K$23,A35)>0,"Yes","No") -> No
A36: William White | B36: =UPPER(LEFT(A36,1)&MID(A36,FIND(" ",A36)+1,1))&"-"&TEXT(F36,"00") -> WW-23 | C36: =COUNTIFS('Raw Data'!$D$2:$D$251,A36) -> 3 | D36: =SUMIFS('Raw Data'!$N$2:$N$251,'Raw Data'!$D$2:$D$251,A36) -> 4749.91 | E36: =IFERROR(D36/C36,0) -> 1583.3033 | F36: =RANK(D36,$D$14:$D$63) -> 23 | G36: =IF(D36>=$B$12,"High-Value","Regular") -> Regular | H36: =IF(COUNTIF($K$14:$K$23,A36)>0,"Yes","No") -> No
... A63: James Johnson | B63: =UPPER(LEFT(A63,1)&MID(A63,FIND(" ",A63)+1,1))&"-"&TEXT(F63,"00") -> JJ-50 | C63: =COUNTIFS('Raw Data'!$D$2:$D$251,A63) -> 1 | D63: =SUMIFS('Raw Data'!$N$2:$N$251,'Raw Data'!$D$2:$D$251,A63) -> 179.97 | E63: =IFERROR(D63/C63,0) -> 179.97 | F63: =RANK(D63,$D$14:$D$63) -> 50 | G63: =IF(D63>=$B$12,"High-Value","Regular") -> Regular | H63: =IF(COUNTIF($K$14:$K$23,A63)>0,"Yes","No") -> No
A64: Total | C64: =SUM(C14:C63) -> 250 | D64: =SUM(D14:D63) -> 229192.47
A65: Top customer | B65: =INDEX(A14:A63,MATCH(MAX(D14:D63),D14:D63,0)) -> Mark Carter
A66: High-value customers (count) | B66: =COUNTIF(G14:G63,"High-Value") -> 13
A68: 3. Products – most frequently purchased
...

Sheet Filter
A1: FILTER-style multi-value return (works in every Excel version)
A2: Pick a region → | B2: West | H2: Shows first 25 matches. Excel 365 alternative: =FILTER('Raw Data'!A2:N251,'Raw Data'!K2:K251=B2)
A3: Matching transactions | B3: =COUNTIF('Raw Data'!$K$2:$K$251,B2) -> 47
A4: Revenue for region | B4: =SUMIFS('Raw Data'!$N$2:$N$251,'Raw Data'!$K$2:$K$251,B2) -> 41408.68
A6: # | B6: Transaction ID | C6: Date | D6: Customer | E6: Product | F6: Total Amount
A7: 1 | B7: =IFERROR(INDEX('Raw Data'!$A$2:$A$251,MATCH($A7,'Raw Data'!$Q$2:$Q$251,0)),"") -> TRX0092 | C7: =IFERROR(INDEX('Raw Data'!$B$2:$B$251,MATCH($A7,'Raw Data'!$Q$2:$Q$251,0)),"") -> 45403 | D7: =IFERROR(INDEX('Raw Data'!$D$2:$D$251,MATCH($A7,'Raw Data'!$Q$2:$Q$251,0)),"") -> Dorothy Nelson | E7: =IFERROR(INDEX('Raw Data'!$F$2:$F$251,MATCH($A7,'Raw Data'!$Q$2:$Q$251,0)),"") -> Blender | F7: =IFERROR(INDEX('Raw Data'!$N$2:$N$251,MATCH($A7,'Raw Data'!$Q$2:$Q$251,0)),"") -> 119.98
A8: 2 | B8: =IFERROR(INDEX('Raw Data'!$A$2:$A$251,MATCH($A8,'Raw Data'!$Q$2:$Q$251,0)),"") -> TRX0185 | C8: =IFERROR(INDEX('Raw Data'!$B$2:$B$251,MATCH($A8,'Raw Data'!$Q$2:$Q$251,0)),"") -> 45408 | D8: =IFERROR(INDEX('Raw Data'!$D$2:$D$251,MATCH($A8,'Raw Data'!$Q$2:$Q$251,0)),"") -> Karen Hill | E8: =IFERROR(INDEX('Raw Data'!$F$2:$F$251,MATCH($A8,'Raw Data'!$Q$2:$Q$251,0)),"") -> Blender | F8: =IFERROR(INDEX('Raw Data'!$N$2:$N$251,MATCH($A8,'Raw Data'!$Q$2:$Q$251,0)),"") -> 179.97
A9: 3 | B9: =IFERROR(INDEX('Raw Data'!$A$2:$A$251,MATCH($A9,'Raw Data'!$Q$2:$Q$251,0)),"") -> TRX0138 | C9: =IFERROR(INDEX('Raw Data'!$B$2:$B$251,MATCH($A9,'Raw Data'!$Q$2:$Q$251,0)),"") -> 45408 | D9: =IFERROR(INDEX('Raw Data'!$D$2:$D$251,MATCH($A9,'Raw Data'!$Q$2:$Q$251,0)),"") -> Susan Green | E9: =IFERROR(INDEX('Raw Data'!$F$2:$F$251,MATCH($A9,'Raw Data'!$Q$2:$Q$251,0)),"") -> Bookshelf | F9: =IFERROR(INDEX('Raw Data'!$N$2:$N$251,MATCH($A9,'Raw Data'!$Q$2:$Q$251,0)),"") -> 149.99
A10: 4 | B10: =IFERROR(INDEX('Raw Data'!$A$2:$A$251,MATCH($A10,'Raw Data'!$Q$2:$Q$251,0)),"") -> TRX0191 | C10: =IFERROR(INDEX('Raw Data'!$B$2:$B$251,MATCH($A10,'Raw Data'!$Q$2:$Q$251,0)),"") -> 45409 | D10: =IFERROR(INDEX('Raw Data'!$D$2:$D$251,MATCH($A10,'Raw Data'!$Q$2:$Q$251,0)),"") -> Michelle Rogers | E10: =IFERROR(INDEX('Raw Data'!$F$2:$F$251,MATCH($A10,'Raw Data'!$Q$2:$Q$251,0)),"") -> Smartphone | F10: =IFERROR(INDEX('Raw Data'!$N$2:$N$251,MATCH($A10,'Raw Data'!$Q$2:$Q$251,0)),"") -> 2099.97
A11: 5 | B11: =IFERROR(INDEX('Raw Data'!$A$2:$A$251,MATCH($A11,'Raw Data'!$Q$2:$Q$251,0)),"") -> TRX0122 | C11: =IFERROR(INDEX('Raw Data'!$B$2:$B$251,MATCH($A11,'Raw Data'!$Q$2:$Q$251,0)),"") -> 45410 | D11: =IFERROR(INDEX('Raw Data'!$D$2:$D$251,MATCH($A11,'Raw Data'!$Q$2:$Q$251,0)),"") -> Mark Carter | E11: =IFERROR(INDEX('Raw Data'!$F$2:$F$251,MATCH($A11,'Raw Data'!$Q$2:$Q$251,0)),"") -> Laptop | F11: =IFERROR(INDEX('Raw Data'!$N$2:$N$251,MATCH($A11,'Raw Data'!$Q$2:$Q$251,0)),"") -> 3599.96
A12: 6 | B12: =IFERROR(INDEX('Raw Data'!$A$2:$A$251,MATCH($A12,'Raw Data'!$Q$2:$Q$251,0)),"") -> TRX0231 | C12: =IFERROR(INDEX('Raw Data'!$B$2:$B$251,MATCH($A12,'Raw Data'!$Q$2:$Q$251,0)),"") -> 45412 | D12: =IFERROR(INDEX('Raw Data'!$D$2:$D$251,MATCH($A12,'Raw Data'!$Q$2:$Q$251,0)),"") -> Barbara Young | E12: =IFERROR(INDEX('Raw Data'!$F$2:$F$251,MATCH($A12,'Raw Data'!$Q$2:$Q$251,0)),"") -> Smartphone | F12: =IFERROR(INDEX('Raw Data'!$N$2:$N$251,MATCH($A12,'Raw Data'!$Q$2:$Q$251,0)),"") -> 3499.95
A13: 7 | B13: =IFERROR(INDEX('Raw Data'!$A$2:$A$251,MATCH($A13,'Raw Data'!$Q$2:$Q$251,0)),"") -> TRX0242 | C13: =IFERROR(INDEX('Raw Data'!$B$2:$B$251,MATCH($A13,'Raw Data'!$Q$2:$Q$251,0)),"") -> 45416 | D13: =IFERROR(INDEX('Raw Data'!$D$2:$D$251,MATCH($A13,'Raw Data'!$Q$2:$Q$251,0)),"") -> Mark Carter | E13: =IFERROR(INDEX('Raw Data'!$F$2:$F$251,MATCH($A13,'Raw Data'!$Q$2:$Q$251,0)),"") -> Desk | F13: =IFERROR(INDEX('Raw Data'!$N$2:$N$251,MATCH($A13,'Raw Data'!$Q$2:$Q$251,0)),"") -> 1199.96
A14: 8 | B14: =IFERROR(INDEX('Raw Data'!$A$2:$A$251,MATCH($A14,'Raw Data'!$Q$2:$Q$251,0)),"") -> TRX0071 | C14: =IFERROR(INDEX('Raw Data'!$B$2:$B$251,MATCH($A14,'Raw Data'!$Q$2:$Q$251,0)),"") -> 45422 | D14: =IFERROR(INDEX('Raw Data'!$D$2:$D$251,MATCH($A14,'Raw Data'!$Q$2:$Q$251,0)),"") -> Nancy Collins | E14: =IFERROR(INDEX('Raw Data'!$F$2:$F$251,MATCH($A14,'Raw Data'!$Q$2:$Q$251,0)),"") -> Monitor | F14: =IFERROR(INDEX('Raw Data'!$N$2:$N$251,MATCH($A14,'Raw Data'!$Q$2:$Q$251,0)),"") -> 1249.95
A15: 9 | B15: =IFERROR(INDEX('Raw Data'!$A$2:$A$251,MATCH($A15,'Raw Data'!$Q$2:$Q$251,0)),"") -> TRX0194 | C15: =IFERROR(INDEX('Raw Data'!$B$2:$B$251,MATCH($A15,'Raw Data'!$Q$2:$Q$251,0)),"") -> 45428 | D15: =IFERROR(INDEX('Raw Data'!$D$2:$D$251,MATCH($A15,'Raw Data'!$Q$2:$Q$251,0)),"") -> Lisa Anderson | E15: =IFERROR(INDEX('Raw Data'!$F$2:$F$251,MATCH($A15,'Raw Data'!$Q$2:$Q$251,0)),"") -> Bookshelf | F15: =IFERROR(INDEX('Raw Data'!$N$2:$N$251,MATCH($A15,'Raw Data'!$Q$2:$Q$251,0)),"") -> 299.98
A16: 10 | B16: =IFERROR(INDEX('Raw Data'!$A$2:$A$251,MATCH($A16,'Raw Data'!$Q$2:$Q$251,0)),"") -> TRX0130 | C16: =IFERROR(INDEX('Raw Data'!$B$2:$B$251,MATCH($A16,'Raw Data'!$Q$2:$Q$251,0)),"") -> 45430 | D16: =IFERROR(INDEX('Raw Data'!$D$2:$D$251,MATCH($A16,'Raw Data'!$Q$2:$Q$251,0)),"") -> Emma Wilson | E16: =IFERROR(INDEX('Raw Data'!$F$2:$F$251,MATCH($A16,'Raw Data'!$Q$2:$Q$251,0)),"") -> Bookshelf | F16: =IFERROR(INDEX('Raw Data'!$N$2:$N$251,MATCH($A16,'Raw Data'!$Q$2:$Q$251,0)),"") -> 449.97
A17: 11 | B17: =IFERROR(INDEX('Raw Data'!$A$2:$A$251,MATCH($A17,'Raw Data'!$Q$2:$Q$251,0)),"") -> TRX0041 | C17: =IFERROR(INDEX('Raw Data'!$B$2:$B$251,MATCH($A17,'Raw Data'!$Q$2:$Q$251,0)),"") -> 45432 | D17: =IFERROR(INDEX('Raw Data'!$D$2:$D$251,MATCH($A17,'Raw Data'!$Q$2:$Q$251,0)),"") -> Kevin Scott | E17: =IFERROR(INDEX('Raw Data'!$F$2:$F$251,MATCH($A17,'Raw Data'!$Q$2:$Q$251,0)),"") -> Laptop | F17: =IFERROR(INDEX('Raw Data'!$N$2:$N$251,MATCH($A17,'Raw Data'!$Q$2:$Q$251,0)),"") -> 899.99
A18: 12 | B18: =IFERROR(INDEX('Raw Data'!$A$2:$A$251,MATCH($A18,'Raw Data'!$Q$2:$Q$251,0)),"") -> TRX0015 | C18: =IFERROR(INDEX('Raw Data'!$B$2:$B$251,MATCH($A18,'Raw Data'!$Q$2:$Q$251,0)),"") -> 45440 | D18: =IFERROR(INDEX('Raw Data'!$D$2:$D$251,MATCH($A18,'Raw Data'!$Q$2:$Q$251,0)),"") -> Jennifer Taylor | E18: =IFERROR(INDEX('Raw Data'!$F$2:$F$251,MATCH($A18,'Raw Data'!$Q$2:$Q$251,0)),"") -> Smartphone | F18: =IFERROR(INDEX('Raw Data'!$N$2:$N$251,MATCH($A18,'Raw Data'!$Q$2:$Q$251,0)),"") -> 3499.95
... A31: 25 | B31: =IFERROR(INDEX('Raw Data'!$A$2:$A$251,MATCH($A31,'Raw Data'!$Q$2:$Q$251,0)),"") -> TRX0172 | C31: =IFERROR(INDEX('Raw Data'!$B$2:$B$251,MATCH($A31,'Raw Data'!$Q$2:$Q$251,0)),"") -> 45607 | D31: =IFERROR(INDEX('Raw Data'!$D$2:$D$251,MATCH($A31,'Raw Data'!$Q$2:$Q$251,0)),"") -> Paul Baker | E31: =IFERROR(INDEX('Raw Data'!$F$2:$F$251,MATCH($A31,'Raw Data'!$Q$2:$Q$251,0)),"") -> Blender | F31: =IFERROR(INDEX('Raw Data'!$N$2:$N$251,MATCH($A31,'Raw Data'!$Q$2:$Q$251,0)),"") -> 299.95

Sheet What-If
A1: What-If Analysis – Scenario Manager & Goal Seek
A3: Assumption | B3: Value
A4: Baseline revenue ($) | B4: =SUM('Raw Data'!$N$2:$N$251) -> 229192.47
A5: Price change % | B5: 0.05
A6: Volume change % | B6: 0.02
A7: Discount % | B7: 0.03
A8: Scenario revenue ($) | B8: =B4*(1+B5)*(1+B6)*(1-B7) -> 238101.18
A9: Change vs baseline ($) | B9: =B8-B4 -> 8908.7113
A11: Scenario comparison (or build with Data > What-If > Scenario Manager)
A12: Scenario | B12: Price % | C12: Volume % | D12: Discount % | E12: Revenue ($)
A13: Best case | B13: 0.1 | C13: 0.08 | D13: 0.01 | E13: =$B$4*(1+B13)*(1+C13)*(1-D13) -> 269557.85
A14: Base case | B14: 0.05 | C14: 0.02 | D14: 0.03 | E14: =$B$4*(1+B14)*(1+C14)*(1-D14) -> 238101.18
A15: Worst case | B15: -0.02 | C15: -0.05 | D15: 0.06 | E15: =$B$4*(1+B15)*(1+C15)*(1-D15) -> 200575.5
A17: Goal Seek
A18: Target revenue ($) = baseline +10% | B18: =B4*1.1 -> 252111.72
A19: Required price change (closed-form check) | B19: =B18/(B4*(1+B6)*(1-B7))-1 -> 0.11178492
A20: Run Goal Seek: Data > What-If Analysis > Goal Seek → Set cell B8, To value = B18, By changing B5. Result should match B19.

Sheet Regression
A1: Linear Regression: Quantity (X) → Total Amount (Y)
A3: Statistic | B3: Value
A4: Slope ($ per extra unit) | B4: =SLOPE('Raw Data'!$N$2:$N$251,'Raw Data'!$H$2:$H$251) -> 353.793
A5: Intercept | B5: =INTERCEPT('Raw Data'!$N$2:$N$251,'Raw Data'!$H$2:$H$251) -> -148.85465
A6: R² | B6: =RSQ('Raw Data'!$N$2:$N$251,'Raw Data'!$H$2:$H$251) -> 0.20983762
A7: Correlation (r) | B7: =CORREL('Raw Data'!$N$2:$N$251,'Raw Data'!$H$2:$H$251) -> 0.45808036
A8: Std. error of estimate | B8: =STEYX('Raw Data'!$N$2:$N$251,'Raw Data'!$H$2:$H$251) -> 919.60715
A9: Observations | B9: =COUNT('Raw Data'!$H$2:$H$251) -> 250
A11: Predict revenue for quantity → | B11: 4
A12: Predicted revenue | B12: =B5+B4*B11 -> 1266.3174
A14: Also run: Data > Data Analysis > Regression (Y = Raw Data N2:N251, X = H2:H251). See Guide sheet.

Sheet Visualizations
A1: Visualizations (all charts linked to the Analysis sheet)

Sheet Final Report
A1: Final Report – Insights & Storytelling (text updates automatically)
A3: Headline | B3: ="Between "&TEXT(Analysis!B6,"dd-mmm-yyyy")&" and "&TEXT(Analysis!B7,"dd-mmm-yyyy")&", "&TEXT(Dashboard!C4,"#,##0")&" orders generated total revenue of $"&TEXT(Dashboard!A4,"#,##0")&", an average of $"&TEXT(Dashboard!E4,"#,##0.00")&" per order." -> Between 11-Apr-2024 and 11-Apr-2025, 250 orders generated total revenue of $229,192, an average of $916.77 per order.
A4: Customers | B4: ="Our top customer is "&Analysis!B65&". "&Analysis!B66&" of "&Dashboard!G4&" customers are High-Value (revenue ≥ $"&TEXT(Analysis!B12,"#,##0")&") and they drive "&TEXT(SUMIFS(Analysis!D14:D63,Analysis!G14:G63,"High-Value")/Analysis!D64,"0%")&" of revenue." -> Our top customer is Mark Carter. 13 of 50 customers are High-Value (revenue ≥ $6,305) and they drive 49% of revenue.
A5: Products | B5: ="Most frequently purchased: "&Analysis!B81&". Highest revenue: "&Analysis!B83&" ("&TEXT(MAX(Analysis!F70:F79),"0%")&" of revenue)." -> Most frequently purchased: Bookshelf. Highest revenue: Laptop (29% of revenue).
A6: Regions | B6: ="Best region: "&Analysis!B93&" with $"&TEXT(MAX(Analysis!C87:C91),"#,##0")&" ("&TEXT(MAX(Analysis!D87:D91),"0%")&" share); weakest region earned $"&TEXT(MIN(Analysis!C87:C91),"#,##0")&"." -> Best region: East with $59,288 (26% share); weakest region earned $36,399.
A7: Trend | B7: ="Last full month ("&TEXT(Analysis!A127,"mmm-yy")&") revenue was $"&TEXT(Analysis!C127,"#,##0")&", "&IF(Analysis!F127>=0,"up ","down ")&TEXT(ABS(Analysis!F127),"0.0%")&" versus the prior month." -> Last full month (Mar-25) revenue was $19,899, up 23.8% versus the prior month.
A8: Relationship | B8: ="Each extra unit in an order adds about $"&TEXT(Regression!B4,"#,##0")&" in revenue (R² = "&TEXT(Regression!B6,"0.00")&")." -> Each extra unit in an order adds about $354 in revenue (R² = 0.21).
A9: What-If | B9: ="Base-case scenario revenue is $"&TEXT('What-If'!E14,"#,##0")&" versus best case $"&TEXT('What-If'!E13,"#,##0")&" and worst case $"&TEXT('What-If'!E15,"#,##0")&"." -> Base-case scenario revenue is $238,101 versus best case $269,558 and worst case $200,575.
A10: Recommendation | B10: Focus retention on High-Value customers, keep the best-selling products in stock, and push campaigns in the weakest regions and months flagged red on the Analysis sheet.
